[2023-07-13 15:26:41,639] * [ERROR] Internal Server Error: /news/css/styles.css C:\Users\flyin\PycharmProjects\skillFactory_D\venv\lib\site-packages\django\utils\log.py (<class 'django.db.utils.ProgrammingError'>, ProgrammingError('ОШИБКА:  отношение "django_site" не существует\nLINE 1: ..."django_site"."domain", "django_site"."name" FROM "django_si...\n                                                             ^\n'), <traceback object at 0x000001ED3DB91700>)
Traceback (most recent call last):
  File "C:\Users\flyin\PycharmProjects\skillFactory_D\venv\lib\site-packages\django\db\backends\utils.py", line 89, in _execute
    return self.cursor.execute(sql, params)
psycopg2.errors.UndefinedTable: ОШИБКА:  отношение "django_site" не существует
LINE 1: ..."django_site"."domain", "django_site"."name" FROM "django_si...
                                                             ^


The above exception was the direct cause of the following exception:

Traceback (most recent call last):
  File "C:\Users\flyin\PycharmProjects\skillFactory_D\venv\lib\site-packages\django\core\handlers\exception.py", line 55, in inner
    response = get_response(request)
  File "C:\Users\flyin\PycharmProjects\skillFactory_D\venv\lib\site-packages\django\utils\deprecation.py", line 136, in __call__
    response = self.process_response(request, response)
  File "C:\Users\flyin\PycharmProjects\skillFactory_D\venv\lib\site-packages\django\contrib\flatpages\middleware.py", line 12, in process_response
    return flatpage(request, request.path_info)
  File "C:\Users\flyin\PycharmProjects\skillFactory_D\venv\lib\site-packages\django\contrib\flatpages\views.py", line 35, in flatpage
    site_id = get_current_site(request).id
  File "C:\Users\flyin\PycharmProjects\skillFactory_D\venv\lib\site-packages\django\contrib\sites\shortcuts.py", line 16, in get_current_site
    return Site.objects.get_current(request)
  File "C:\Users\flyin\PycharmProjects\skillFactory_D\venv\lib\site-packages\django\contrib\sites\models.py", line 59, in get_current
    return self._get_site_by_id(site_id)
  File "C:\Users\flyin\PycharmProjects\skillFactory_D\venv\lib\site-packages\django\contrib\sites\models.py", line 30, in _get_site_by_id
    site = self.get(pk=site_id)
  File "C:\Users\flyin\PycharmProjects\skillFactory_D\venv\lib\site-packages\django\db\models\manager.py", line 87, in manager_method
    return getattr(self.get_queryset(), name)(*args, **kwargs)
  File "C:\Users\flyin\PycharmProjects\skillFactory_D\venv\lib\site-packages\django\db\models\query.py", line 633, in get
    num = len(clone)
  File "C:\Users\flyin\PycharmProjects\skillFactory_D\venv\lib\site-packages\django\db\models\query.py", line 380, in __len__
    self._fetch_all()
  File "C:\Users\flyin\PycharmProjects\skillFactory_D\venv\lib\site-packages\django\db\models\query.py", line 1881, in _fetch_all
    self._result_cache = list(self._iterable_class(self))
  File "C:\Users\flyin\PycharmProjects\skillFactory_D\venv\lib\site-packages\django\db\models\query.py", line 91, in __iter__
    results = compiler.execute_sql(
  File "C:\Users\flyin\PycharmProjects\skillFactory_D\venv\lib\site-packages\django\db\models\sql\compiler.py", line 1562, in execute_sql
    cursor.execute(sql, params)
  File "C:\Users\flyin\PycharmProjects\skillFactory_D\venv\lib\site-packages\django\db\backends\utils.py", line 102, in execute
    return super().execute(sql, params)
  File "C:\Users\flyin\PycharmProjects\skillFactory_D\venv\lib\site-packages\django\db\backends\utils.py", line 67, in execute
    return self._execute_with_wrappers(
  File "C:\Users\flyin\PycharmProjects\skillFactory_D\venv\lib\site-packages\django\db\backends\utils.py", line 80, in _execute_with_wrappers
    return executor(sql, params, many, context)
  File "C:\Users\flyin\PycharmProjects\skillFactory_D\venv\lib\site-packages\django\db\backends\utils.py", line 89, in _execute
    return self.cursor.execute(sql, params)
  File "C:\Users\flyin\PycharmProjects\skillFactory_D\venv\lib\site-packages\django\db\utils.py", line 91, in __exit__
    raise dj_exc_value.with_traceback(traceback) from exc_value
  File "C:\Users\flyin\PycharmProjects\skillFactory_D\venv\lib\site-packages\django\db\backends\utils.py", line 89, in _execute
    return self.cursor.execute(sql, params)
django.db.utils.ProgrammingError: ОШИБКА:  отношение "django_site" не существует
LINE 1: ..."django_site"."domain", "django_site"."name" FROM "django_si...
                                                             ^

[2023-07-13 15:26:41,679] * [ERROR] "GET /news/css/styles.css HTTP/1.1" 500 149045 C:\Users\flyin\PycharmProjects\skillFactory_D\venv\lib\site-packages\django\core\servers\basehttp.py None
[2023-07-13 15:26:42,228] * [ERROR] Internal Server Error: /news/css/styles.css C:\Users\flyin\PycharmProjects\skillFactory_D\venv\lib\site-packages\django\utils\log.py (<class 'django.db.utils.ProgrammingError'>, ProgrammingError('ОШИБКА:  отношение "django_site" не существует\nLINE 1: ..."django_site"."domain", "django_site"."name" FROM "django_si...\n                                                             ^\n'), <traceback object at 0x000001ED3DFB2A00>)
Traceback (most recent call last):
  File "C:\Users\flyin\PycharmProjects\skillFactory_D\venv\lib\site-packages\django\db\backends\utils.py", line 89, in _execute
    return self.cursor.execute(sql, params)
psycopg2.errors.UndefinedTable: ОШИБКА:  отношение "django_site" не существует
LINE 1: ..."django_site"."domain", "django_site"."name" FROM "django_si...
                                                             ^


The above exception was the direct cause of the following exception:

Traceback (most recent call last):
  File "C:\Users\flyin\PycharmProjects\skillFactory_D\venv\lib\site-packages\django\core\handlers\exception.py", line 55, in inner
    response = get_response(request)
  File "C:\Users\flyin\PycharmProjects\skillFactory_D\venv\lib\site-packages\django\utils\deprecation.py", line 136, in __call__
    response = self.process_response(request, response)
  File "C:\Users\flyin\PycharmProjects\skillFactory_D\venv\lib\site-packages\django\contrib\flatpages\middleware.py", line 12, in process_response
    return flatpage(request, request.path_info)
  File "C:\Users\flyin\PycharmProjects\skillFactory_D\venv\lib\site-packages\django\contrib\flatpages\views.py", line 35, in flatpage
    site_id = get_current_site(request).id
  File "C:\Users\flyin\PycharmProjects\skillFactory_D\venv\lib\site-packages\django\contrib\sites\shortcuts.py", line 16, in get_current_site
    return Site.objects.get_current(request)
  File "C:\Users\flyin\PycharmProjects\skillFactory_D\venv\lib\site-packages\django\contrib\sites\models.py", line 59, in get_current
    return self._get_site_by_id(site_id)
  File "C:\Users\flyin\PycharmProjects\skillFactory_D\venv\lib\site-packages\django\contrib\sites\models.py", line 30, in _get_site_by_id
    site = self.get(pk=site_id)
  File "C:\Users\flyin\PycharmProjects\skillFactory_D\venv\lib\site-packages\django\db\models\manager.py", line 87, in manager_method
    return getattr(self.get_queryset(), name)(*args, **kwargs)
  File "C:\Users\flyin\PycharmProjects\skillFactory_D\venv\lib\site-packages\django\db\models\query.py", line 633, in get
    num = len(clone)
  File "C:\Users\flyin\PycharmProjects\skillFactory_D\venv\lib\site-packages\django\db\models\query.py", line 380, in __len__
    self._fetch_all()
  File "C:\Users\flyin\PycharmProjects\skillFactory_D\venv\lib\site-packages\django\db\models\query.py", line 1881, in _fetch_all
    self._result_cache = list(self._iterable_class(self))
  File "C:\Users\flyin\PycharmProjects\skillFactory_D\venv\lib\site-packages\django\db\models\query.py", line 91, in __iter__
    results = compiler.execute_sql(
  File "C:\Users\flyin\PycharmProjects\skillFactory_D\venv\lib\site-packages\django\db\models\sql\compiler.py", line 1562, in execute_sql
    cursor.execute(sql, params)
  File "C:\Users\flyin\PycharmProjects\skillFactory_D\venv\lib\site-packages\django\db\backends\utils.py", line 102, in execute
    return super().execute(sql, params)
  File "C:\Users\flyin\PycharmProjects\skillFactory_D\venv\lib\site-packages\django\db\backends\utils.py", line 67, in execute
    return self._execute_with_wrappers(
  File "C:\Users\flyin\PycharmProjects\skillFactory_D\venv\lib\site-packages\django\db\backends\utils.py", line 80, in _execute_with_wrappers
    return executor(sql, params, many, context)
  File "C:\Users\flyin\PycharmProjects\skillFactory_D\venv\lib\site-packages\django\db\backends\utils.py", line 89, in _execute
    return self.cursor.execute(sql, params)
  File "C:\Users\flyin\PycharmProjects\skillFactory_D\venv\lib\site-packages\django\db\utils.py", line 91, in __exit__
    raise dj_exc_value.with_traceback(traceback) from exc_value
  File "C:\Users\flyin\PycharmProjects\skillFactory_D\venv\lib\site-packages\django\db\backends\utils.py", line 89, in _execute
    return self.cursor.execute(sql, params)
django.db.utils.ProgrammingError: ОШИБКА:  отношение "django_site" не существует
LINE 1: ..."django_site"."domain", "django_site"."name" FROM "django_si...
                                                             ^

[2023-07-13 15:26:42,264] * [ERROR] "GET /news/css/styles.css HTTP/1.1" 500 149045 C:\Users\flyin\PycharmProjects\skillFactory_D\venv\lib\site-packages\django\core\servers\basehttp.py None
[2023-07-13 15:26:44,136] * [ERROR] Internal Server Error: /news/ C:\Users\flyin\PycharmProjects\skillFactory_D\venv\lib\site-packages\django\utils\log.py (<class 'django.db.utils.ProgrammingError'>, ProgrammingError('ОШИБКА:  отношение "news_news" не существует\nLINE 1: SELECT COUNT(*) AS "__count" FROM "news_news"\n                                          ^\n'), <traceback object at 0x000001ED3DD86E80>)
Traceback (most recent call last):
  File "C:\Users\flyin\PycharmProjects\skillFactory_D\venv\lib\site-packages\django\db\backends\utils.py", line 89, in _execute
    return self.cursor.execute(sql, params)
psycopg2.errors.UndefinedTable: ОШИБКА:  отношение "news_news" не существует
LINE 1: SELECT COUNT(*) AS "__count" FROM "news_news"
                                          ^


The above exception was the direct cause of the following exception:

Traceback (most recent call last):
  File "C:\Users\flyin\PycharmProjects\skillFactory_D\venv\lib\site-packages\django\core\handlers\exception.py", line 55, in inner
    response = get_response(request)
  File "C:\Users\flyin\PycharmProjects\skillFactory_D\venv\lib\site-packages\django\core\handlers\base.py", line 197, in _get_response
    response = wrapped_callback(request, *callback_args, **callback_kwargs)
  File "C:\Users\flyin\PycharmProjects\skillFactory_D\venv\lib\site-packages\django\views\generic\base.py", line 104, in view
    return self.dispatch(request, *args, **kwargs)
  File "C:\Users\flyin\PycharmProjects\skillFactory_D\venv\lib\site-packages\django\views\generic\base.py", line 143, in dispatch
    return handler(request, *args, **kwargs)
  File "C:\Users\flyin\PycharmProjects\skillFactory_D\venv\lib\site-packages\django\views\generic\list.py", line 174, in get
    context = self.get_context_data()
  File "C:\Users\flyin\PycharmProjects\skillFactory_D\project\news\views.py", line 30, in get_context_data
    context = super().get_context_data(**kwargs)
  File "C:\Users\flyin\PycharmProjects\skillFactory_D\venv\lib\site-packages\django\views\generic\list.py", line 128, in get_context_data
    paginator, page, queryset, is_paginated = self.paginate_queryset(
  File "C:\Users\flyin\PycharmProjects\skillFactory_D\venv\lib\site-packages\django\views\generic\list.py", line 73, in paginate_queryset
    page = paginator.page(page_number)
  File "C:\Users\flyin\PycharmProjects\skillFactory_D\venv\lib\site-packages\django\core\paginator.py", line 72, in page
    number = self.validate_number(number)
  File "C:\Users\flyin\PycharmProjects\skillFactory_D\venv\lib\site-packages\django\core\paginator.py", line 53, in validate_number
    if number > self.num_pages:
  File "C:\Users\flyin\PycharmProjects\skillFactory_D\venv\lib\site-packages\django\utils\functional.py", line 57, in __get__
    res = instance.__dict__[self.name] = self.func(instance)
  File "C:\Users\flyin\PycharmProjects\skillFactory_D\venv\lib\site-packages\django\core\paginator.py", line 99, in num_pages
    if self.count == 0 and not self.allow_empty_first_page:
  File "C:\Users\flyin\PycharmProjects\skillFactory_D\venv\lib\site-packages\django\utils\functional.py", line 57, in __get__
    res = instance.__dict__[self.name] = self.func(instance)
  File "C:\Users\flyin\PycharmProjects\skillFactory_D\venv\lib\site-packages\django\core\paginator.py", line 93, in count
    return c()
  File "C:\Users\flyin\PycharmProjects\skillFactory_D\venv\lib\site-packages\django\db\models\query.py", line 608, in count
    return self.query.get_count(using=self.db)
  File "C:\Users\flyin\PycharmProjects\skillFactory_D\venv\lib\site-packages\django\db\models\sql\query.py", line 557, in get_count
    return obj.get_aggregation(using, {"__count": Count("*")})["__count"]
  File "C:\Users\flyin\PycharmProjects\skillFactory_D\venv\lib\site-packages\django\db\models\sql\query.py", line 543, in get_aggregation
    result = compiler.execute_sql(SINGLE)
  File "C:\Users\flyin\PycharmProjects\skillFactory_D\venv\lib\site-packages\django\db\models\sql\compiler.py", line 1562, in execute_sql
    cursor.execute(sql, params)
  File "C:\Users\flyin\PycharmProjects\skillFactory_D\venv\lib\site-packages\django\db\backends\utils.py", line 102, in execute
    return super().execute(sql, params)
  File "C:\Users\flyin\PycharmProjects\skillFactory_D\venv\lib\site-packages\django\db\backends\utils.py", line 67, in execute
    return self._execute_with_wrappers(
  File "C:\Users\flyin\PycharmProjects\skillFactory_D\venv\lib\site-packages\django\db\backends\utils.py", line 80, in _execute_with_wrappers
    return executor(sql, params, many, context)
  File "C:\Users\flyin\PycharmProjects\skillFactory_D\venv\lib\site-packages\django\db\backends\utils.py", line 89, in _execute
    return self.cursor.execute(sql, params)
  File "C:\Users\flyin\PycharmProjects\skillFactory_D\venv\lib\site-packages\django\db\utils.py", line 91, in __exit__
    raise dj_exc_value.with_traceback(traceback) from exc_value
  File "C:\Users\flyin\PycharmProjects\skillFactory_D\venv\lib\site-packages\django\db\backends\utils.py", line 89, in _execute
    return self.cursor.execute(sql, params)
django.db.utils.ProgrammingError: ОШИБКА:  отношение "news_news" не существует
LINE 1: SELECT COUNT(*) AS "__count" FROM "news_news"
                                          ^

[2023-07-13 15:26:44,188] * [ERROR] "GET /news/ HTTP/1.1" 500 175383 C:\Users\flyin\PycharmProjects\skillFactory_D\venv\lib\site-packages\django\core\servers\basehttp.py None
[2023-07-13 15:26:49,339] * [ERROR] Internal Server Error: /news/css/styles.css C:\Users\flyin\PycharmProjects\skillFactory_D\venv\lib\site-packages\django\utils\log.py (<class 'django.db.utils.ProgrammingError'>, ProgrammingError('ОШИБКА:  отношение "django_site" не существует\nLINE 1: ..."django_site"."domain", "django_site"."name" FROM "django_si...\n                                                             ^\n'), <traceback object at 0x000001ED3DF70180>)
Traceback (most recent call last):
  File "C:\Users\flyin\PycharmProjects\skillFactory_D\venv\lib\site-packages\django\db\backends\utils.py", line 89, in _execute
    return self.cursor.execute(sql, params)
psycopg2.errors.UndefinedTable: ОШИБКА:  отношение "django_site" не существует
LINE 1: ..."django_site"."domain", "django_site"."name" FROM "django_si...
                                                             ^


The above exception was the direct cause of the following exception:

Traceback (most recent call last):
  File "C:\Users\flyin\PycharmProjects\skillFactory_D\venv\lib\site-packages\django\core\handlers\exception.py", line 55, in inner
    response = get_response(request)
  File "C:\Users\flyin\PycharmProjects\skillFactory_D\venv\lib\site-packages\django\utils\deprecation.py", line 136, in __call__
    response = self.process_response(request, response)
  File "C:\Users\flyin\PycharmProjects\skillFactory_D\venv\lib\site-packages\django\contrib\flatpages\middleware.py", line 12, in process_response
    return flatpage(request, request.path_info)
  File "C:\Users\flyin\PycharmProjects\skillFactory_D\venv\lib\site-packages\django\contrib\flatpages\views.py", line 35, in flatpage
    site_id = get_current_site(request).id
  File "C:\Users\flyin\PycharmProjects\skillFactory_D\venv\lib\site-packages\django\contrib\sites\shortcuts.py", line 16, in get_current_site
    return Site.objects.get_current(request)
  File "C:\Users\flyin\PycharmProjects\skillFactory_D\venv\lib\site-packages\django\contrib\sites\models.py", line 59, in get_current
    return self._get_site_by_id(site_id)
  File "C:\Users\flyin\PycharmProjects\skillFactory_D\venv\lib\site-packages\django\contrib\sites\models.py", line 30, in _get_site_by_id
    site = self.get(pk=site_id)
  File "C:\Users\flyin\PycharmProjects\skillFactory_D\venv\lib\site-packages\django\db\models\manager.py", line 87, in manager_method
    return getattr(self.get_queryset(), name)(*args, **kwargs)
  File "C:\Users\flyin\PycharmProjects\skillFactory_D\venv\lib\site-packages\django\db\models\query.py", line 633, in get
    num = len(clone)
  File "C:\Users\flyin\PycharmProjects\skillFactory_D\venv\lib\site-packages\django\db\models\query.py", line 380, in __len__
    self._fetch_all()
  File "C:\Users\flyin\PycharmProjects\skillFactory_D\venv\lib\site-packages\django\db\models\query.py", line 1881, in _fetch_all
    self._result_cache = list(self._iterable_class(self))
  File "C:\Users\flyin\PycharmProjects\skillFactory_D\venv\lib\site-packages\django\db\models\query.py", line 91, in __iter__
    results = compiler.execute_sql(
  File "C:\Users\flyin\PycharmProjects\skillFactory_D\venv\lib\site-packages\django\db\models\sql\compiler.py", line 1562, in execute_sql
    cursor.execute(sql, params)
  File "C:\Users\flyin\PycharmProjects\skillFactory_D\venv\lib\site-packages\django\db\backends\utils.py", line 102, in execute
    return super().execute(sql, params)
  File "C:\Users\flyin\PycharmProjects\skillFactory_D\venv\lib\site-packages\django\db\backends\utils.py", line 67, in execute
    return self._execute_with_wrappers(
  File "C:\Users\flyin\PycharmProjects\skillFactory_D\venv\lib\site-packages\django\db\backends\utils.py", line 80, in _execute_with_wrappers
    return executor(sql, params, many, context)
  File "C:\Users\flyin\PycharmProjects\skillFactory_D\venv\lib\site-packages\django\db\backends\utils.py", line 89, in _execute
    return self.cursor.execute(sql, params)
  File "C:\Users\flyin\PycharmProjects\skillFactory_D\venv\lib\site-packages\django\db\utils.py", line 91, in __exit__
    raise dj_exc_value.with_traceback(traceback) from exc_value
  File "C:\Users\flyin\PycharmProjects\skillFactory_D\venv\lib\site-packages\django\db\backends\utils.py", line 89, in _execute
    return self.cursor.execute(sql, params)
django.db.utils.ProgrammingError: ОШИБКА:  отношение "django_site" не существует
LINE 1: ..."django_site"."domain", "django_site"."name" FROM "django_si...
                                                             ^

[2023-07-13 15:26:49,351] * [ERROR] "GET /news/css/styles.css HTTP/1.1" 500 149045 C:\Users\flyin\PycharmProjects\skillFactory_D\venv\lib\site-packages\django\core\servers\basehttp.py None
[2023-07-13 15:26:49,853] * [ERROR] Internal Server Error: /news/css/styles.css C:\Users\flyin\PycharmProjects\skillFactory_D\venv\lib\site-packages\django\utils\log.py (<class 'django.db.utils.ProgrammingError'>, ProgrammingError('ОШИБКА:  отношение "django_site" не существует\nLINE 1: ..."django_site"."domain", "django_site"."name" FROM "django_si...\n                                                             ^\n'), <traceback object at 0x000001ED3DE62340>)
Traceback (most recent call last):
  File "C:\Users\flyin\PycharmProjects\skillFactory_D\venv\lib\site-packages\django\db\backends\utils.py", line 89, in _execute
    return self.cursor.execute(sql, params)
psycopg2.errors.UndefinedTable: ОШИБКА:  отношение "django_site" не существует
LINE 1: ..."django_site"."domain", "django_site"."name" FROM "django_si...
                                                             ^


The above exception was the direct cause of the following exception:

Traceback (most recent call last):
  File "C:\Users\flyin\PycharmProjects\skillFactory_D\venv\lib\site-packages\django\core\handlers\exception.py", line 55, in inner
    response = get_response(request)
  File "C:\Users\flyin\PycharmProjects\skillFactory_D\venv\lib\site-packages\django\utils\deprecation.py", line 136, in __call__
    response = self.process_response(request, response)
  File "C:\Users\flyin\PycharmProjects\skillFactory_D\venv\lib\site-packages\django\contrib\flatpages\middleware.py", line 12, in process_response
    return flatpage(request, request.path_info)
  File "C:\Users\flyin\PycharmProjects\skillFactory_D\venv\lib\site-packages\django\contrib\flatpages\views.py", line 35, in flatpage
    site_id = get_current_site(request).id
  File "C:\Users\flyin\PycharmProjects\skillFactory_D\venv\lib\site-packages\django\contrib\sites\shortcuts.py", line 16, in get_current_site
    return Site.objects.get_current(request)
  File "C:\Users\flyin\PycharmProjects\skillFactory_D\venv\lib\site-packages\django\contrib\sites\models.py", line 59, in get_current
    return self._get_site_by_id(site_id)
  File "C:\Users\flyin\PycharmProjects\skillFactory_D\venv\lib\site-packages\django\contrib\sites\models.py", line 30, in _get_site_by_id
    site = self.get(pk=site_id)
  File "C:\Users\flyin\PycharmProjects\skillFactory_D\venv\lib\site-packages\django\db\models\manager.py", line 87, in manager_method
    return getattr(self.get_queryset(), name)(*args, **kwargs)
  File "C:\Users\flyin\PycharmProjects\skillFactory_D\venv\lib\site-packages\django\db\models\query.py", line 633, in get
    num = len(clone)
  File "C:\Users\flyin\PycharmProjects\skillFactory_D\venv\lib\site-packages\django\db\models\query.py", line 380, in __len__
    self._fetch_all()
  File "C:\Users\flyin\PycharmProjects\skillFactory_D\venv\lib\site-packages\django\db\models\query.py", line 1881, in _fetch_all
    self._result_cache = list(self._iterable_class(self))
  File "C:\Users\flyin\PycharmProjects\skillFactory_D\venv\lib\site-packages\django\db\models\query.py", line 91, in __iter__
    results = compiler.execute_sql(
  File "C:\Users\flyin\PycharmProjects\skillFactory_D\venv\lib\site-packages\django\db\models\sql\compiler.py", line 1562, in execute_sql
    cursor.execute(sql, params)
  File "C:\Users\flyin\PycharmProjects\skillFactory_D\venv\lib\site-packages\django\db\backends\utils.py", line 102, in execute
    return super().execute(sql, params)
  File "C:\Users\flyin\PycharmProjects\skillFactory_D\venv\lib\site-packages\django\db\backends\utils.py", line 67, in execute
    return self._execute_with_wrappers(
  File "C:\Users\flyin\PycharmProjects\skillFactory_D\venv\lib\site-packages\django\db\backends\utils.py", line 80, in _execute_with_wrappers
    return executor(sql, params, many, context)
  File "C:\Users\flyin\PycharmProjects\skillFactory_D\venv\lib\site-packages\django\db\backends\utils.py", line 89, in _execute
    return self.cursor.execute(sql, params)
  File "C:\Users\flyin\PycharmProjects\skillFactory_D\venv\lib\site-packages\django\db\utils.py", line 91, in __exit__
    raise dj_exc_value.with_traceback(traceback) from exc_value
  File "C:\Users\flyin\PycharmProjects\skillFactory_D\venv\lib\site-packages\django\db\backends\utils.py", line 89, in _execute
    return self.cursor.execute(sql, params)
django.db.utils.ProgrammingError: ОШИБКА:  отношение "django_site" не существует
LINE 1: ..."django_site"."domain", "django_site"."name" FROM "django_si...
                                                             ^

[2023-07-13 15:26:49,868] * [ERROR] "GET /news/css/styles.css HTTP/1.1" 500 149045 C:\Users\flyin\PycharmProjects\skillFactory_D\venv\lib\site-packages\django\core\servers\basehttp.py None
[2023-07-13 15:26:52,163] * [ERROR] Internal Server Error: /accounts/login/ C:\Users\flyin\PycharmProjects\skillFactory_D\venv\lib\site-packages\django\utils\log.py (<class 'django.db.utils.ProgrammingError'>, ProgrammingError('ОШИБКА:  отношение "django_site" не существует\nLINE 1: ..."django_site"."domain", "django_site"."name" FROM "django_si...\n                                                             ^\n'), <traceback object at 0x000001ED3E1C2640>)
Traceback (most recent call last):
  File "C:\Users\flyin\PycharmProjects\skillFactory_D\venv\lib\site-packages\django\db\backends\utils.py", line 89, in _execute
    return self.cursor.execute(sql, params)
psycopg2.errors.UndefinedTable: ОШИБКА:  отношение "django_site" не существует
LINE 1: ..."django_site"."domain", "django_site"."name" FROM "django_si...
                                                             ^


The above exception was the direct cause of the following exception:

Traceback (most recent call last):
  File "C:\Users\flyin\PycharmProjects\skillFactory_D\venv\lib\site-packages\django\core\handlers\exception.py", line 55, in inner
    response = get_response(request)
  File "C:\Users\flyin\PycharmProjects\skillFactory_D\venv\lib\site-packages\django\core\handlers\base.py", line 197, in _get_response
    response = wrapped_callback(request, *callback_args, **callback_kwargs)
  File "C:\Users\flyin\PycharmProjects\skillFactory_D\venv\lib\site-packages\django\views\generic\base.py", line 104, in view
    return self.dispatch(request, *args, **kwargs)
  File "C:\Users\flyin\PycharmProjects\skillFactory_D\venv\lib\site-packages\django\utils\decorators.py", line 46, in _wrapper
    return bound_method(*args, **kwargs)
  File "C:\Users\flyin\PycharmProjects\skillFactory_D\venv\lib\site-packages\django\views\decorators\debug.py", line 92, in sensitive_post_parameters_wrapper
    return view(request, *args, **kwargs)
  File "C:\Users\flyin\PycharmProjects\skillFactory_D\venv\lib\site-packages\allauth\account\views.py", line 149, in dispatch
    return super(LoginView, self).dispatch(request, *args, **kwargs)
  File "C:\Users\flyin\PycharmProjects\skillFactory_D\venv\lib\site-packages\allauth\account\views.py", line 77, in dispatch
    response = super(RedirectAuthenticatedUserMixin, self).dispatch(
  File "C:\Users\flyin\PycharmProjects\skillFactory_D\venv\lib\site-packages\django\views\generic\base.py", line 143, in dispatch
    return handler(request, *args, **kwargs)
  File "C:\Users\flyin\PycharmProjects\skillFactory_D\venv\lib\site-packages\allauth\account\views.py", line 93, in get
    response = super(AjaxCapableProcessFormViewMixin, self).get(
  File "C:\Users\flyin\PycharmProjects\skillFactory_D\venv\lib\site-packages\django\views\generic\edit.py", line 144, in get
    return self.render_to_response(self.get_context_data())
  File "C:\Users\flyin\PycharmProjects\skillFactory_D\venv\lib\site-packages\allauth\account\views.py", line 180, in get_context_data
    site = get_current_site(self.request)
  File "C:\Users\flyin\PycharmProjects\skillFactory_D\venv\lib\site-packages\django\contrib\sites\shortcuts.py", line 16, in get_current_site
    return Site.objects.get_current(request)
  File "C:\Users\flyin\PycharmProjects\skillFactory_D\venv\lib\site-packages\django\contrib\sites\models.py", line 59, in get_current
    return self._get_site_by_id(site_id)
  File "C:\Users\flyin\PycharmProjects\skillFactory_D\venv\lib\site-packages\django\contrib\sites\models.py", line 30, in _get_site_by_id
    site = self.get(pk=site_id)
  File "C:\Users\flyin\PycharmProjects\skillFactory_D\venv\lib\site-packages\django\db\models\manager.py", line 87, in manager_method
    return getattr(self.get_queryset(), name)(*args, **kwargs)
  File "C:\Users\flyin\PycharmProjects\skillFactory_D\venv\lib\site-packages\django\db\models\query.py", line 633, in get
    num = len(clone)
  File "C:\Users\flyin\PycharmProjects\skillFactory_D\venv\lib\site-packages\django\db\models\query.py", line 380, in __len__
    self._fetch_all()
  File "C:\Users\flyin\PycharmProjects\skillFactory_D\venv\lib\site-packages\django\db\models\query.py", line 1881, in _fetch_all
    self._result_cache = list(self._iterable_class(self))
  File "C:\Users\flyin\PycharmProjects\skillFactory_D\venv\lib\site-packages\django\db\models\query.py", line 91, in __iter__
    results = compiler.execute_sql(
  File "C:\Users\flyin\PycharmProjects\skillFactory_D\venv\lib\site-packages\django\db\models\sql\compiler.py", line 1562, in execute_sql
    cursor.execute(sql, params)
  File "C:\Users\flyin\PycharmProjects\skillFactory_D\venv\lib\site-packages\django\db\backends\utils.py", line 102, in execute
    return super().execute(sql, params)
  File "C:\Users\flyin\PycharmProjects\skillFactory_D\venv\lib\site-packages\django\db\backends\utils.py", line 67, in execute
    return self._execute_with_wrappers(
  File "C:\Users\flyin\PycharmProjects\skillFactory_D\venv\lib\site-packages\django\db\backends\utils.py", line 80, in _execute_with_wrappers
    return executor(sql, params, many, context)
  File "C:\Users\flyin\PycharmProjects\skillFactory_D\venv\lib\site-packages\django\db\backends\utils.py", line 89, in _execute
    return self.cursor.execute(sql, params)
  File "C:\Users\flyin\PycharmProjects\skillFactory_D\venv\lib\site-packages\django\db\utils.py", line 91, in __exit__
    raise dj_exc_value.with_traceback(traceback) from exc_value
  File "C:\Users\flyin\PycharmProjects\skillFactory_D\venv\lib\site-packages\django\db\backends\utils.py", line 89, in _execute
    return self.cursor.execute(sql, params)
django.db.utils.ProgrammingError: ОШИБКА:  отношение "django_site" не существует
LINE 1: ..."django_site"."domain", "django_site"."name" FROM "django_si...
                                                             ^

[2023-07-13 15:26:52,192] * [ERROR] "GET /accounts/login/?next=/news/add/ HTTP/1.1" 500 184107 C:\Users\flyin\PycharmProjects\skillFactory_D\venv\lib\site-packages\django\core\servers\basehttp.py None
[2023-07-13 15:27:18,982] * [ERROR] Internal Server Error: /news/css/styles.css C:\Users\flyin\PycharmProjects\skillFactory_D\venv\lib\site-packages\django\utils\log.py (<class 'django.db.utils.ProgrammingError'>, ProgrammingError('ОШИБКА:  отношение "django_site" не существует\nLINE 1: ..."django_site"."domain", "django_site"."name" FROM "django_si...\n                                                             ^\n'), <traceback object at 0x000001ED3E01B140>)
Traceback (most recent call last):
  File "C:\Users\flyin\PycharmProjects\skillFactory_D\venv\lib\site-packages\django\db\backends\utils.py", line 89, in _execute
    return self.cursor.execute(sql, params)
psycopg2.errors.UndefinedTable: ОШИБКА:  отношение "django_site" не существует
LINE 1: ..."django_site"."domain", "django_site"."name" FROM "django_si...
                                                             ^


The above exception was the direct cause of the following exception:

Traceback (most recent call last):
  File "C:\Users\flyin\PycharmProjects\skillFactory_D\venv\lib\site-packages\django\core\handlers\exception.py", line 55, in inner
    response = get_response(request)
  File "C:\Users\flyin\PycharmProjects\skillFactory_D\venv\lib\site-packages\django\utils\deprecation.py", line 136, in __call__
    response = self.process_response(request, response)
  File "C:\Users\flyin\PycharmProjects\skillFactory_D\venv\lib\site-packages\django\contrib\flatpages\middleware.py", line 12, in process_response
    return flatpage(request, request.path_info)
  File "C:\Users\flyin\PycharmProjects\skillFactory_D\venv\lib\site-packages\django\contrib\flatpages\views.py", line 35, in flatpage
    site_id = get_current_site(request).id
  File "C:\Users\flyin\PycharmProjects\skillFactory_D\venv\lib\site-packages\django\contrib\sites\shortcuts.py", line 16, in get_current_site
    return Site.objects.get_current(request)
  File "C:\Users\flyin\PycharmProjects\skillFactory_D\venv\lib\site-packages\django\contrib\sites\models.py", line 59, in get_current
    return self._get_site_by_id(site_id)
  File "C:\Users\flyin\PycharmProjects\skillFactory_D\venv\lib\site-packages\django\contrib\sites\models.py", line 30, in _get_site_by_id
    site = self.get(pk=site_id)
  File "C:\Users\flyin\PycharmProjects\skillFactory_D\venv\lib\site-packages\django\db\models\manager.py", line 87, in manager_method
    return getattr(self.get_queryset(), name)(*args, **kwargs)
  File "C:\Users\flyin\PycharmProjects\skillFactory_D\venv\lib\site-packages\django\db\models\query.py", line 633, in get
    num = len(clone)
  File "C:\Users\flyin\PycharmProjects\skillFactory_D\venv\lib\site-packages\django\db\models\query.py", line 380, in __len__
    self._fetch_all()
  File "C:\Users\flyin\PycharmProjects\skillFactory_D\venv\lib\site-packages\django\db\models\query.py", line 1881, in _fetch_all
    self._result_cache = list(self._iterable_class(self))
  File "C:\Users\flyin\PycharmProjects\skillFactory_D\venv\lib\site-packages\django\db\models\query.py", line 91, in __iter__
    results = compiler.execute_sql(
  File "C:\Users\flyin\PycharmProjects\skillFactory_D\venv\lib\site-packages\django\db\models\sql\compiler.py", line 1562, in execute_sql
    cursor.execute(sql, params)
  File "C:\Users\flyin\PycharmProjects\skillFactory_D\venv\lib\site-packages\django\db\backends\utils.py", line 102, in execute
    return super().execute(sql, params)
  File "C:\Users\flyin\PycharmProjects\skillFactory_D\venv\lib\site-packages\django\db\backends\utils.py", line 67, in execute
    return self._execute_with_wrappers(
  File "C:\Users\flyin\PycharmProjects\skillFactory_D\venv\lib\site-packages\django\db\backends\utils.py", line 80, in _execute_with_wrappers
    return executor(sql, params, many, context)
  File "C:\Users\flyin\PycharmProjects\skillFactory_D\venv\lib\site-packages\django\db\backends\utils.py", line 89, in _execute
    return self.cursor.execute(sql, params)
  File "C:\Users\flyin\PycharmProjects\skillFactory_D\venv\lib\site-packages\django\db\utils.py", line 91, in __exit__
    raise dj_exc_value.with_traceback(traceback) from exc_value
  File "C:\Users\flyin\PycharmProjects\skillFactory_D\venv\lib\site-packages\django\db\backends\utils.py", line 89, in _execute
    return self.cursor.execute(sql, params)
django.db.utils.ProgrammingError: ОШИБКА:  отношение "django_site" не существует
LINE 1: ..."django_site"."domain", "django_site"."name" FROM "django_si...
                                                             ^

[2023-07-13 15:27:19,055] * [ERROR] "GET /news/css/styles.css HTTP/1.1" 500 149045 C:\Users\flyin\PycharmProjects\skillFactory_D\venv\lib\site-packages\django\core\servers\basehttp.py None
[2023-07-13 15:27:19,644] * [ERROR] Internal Server Error: /news/css/styles.css C:\Users\flyin\PycharmProjects\skillFactory_D\venv\lib\site-packages\django\utils\log.py (<class 'django.db.utils.ProgrammingError'>, ProgrammingError('ОШИБКА:  отношение "django_site" не существует\nLINE 1: ..."django_site"."domain", "django_site"."name" FROM "django_si...\n                                                             ^\n'), <traceback object at 0x000001ED3E0076C0>)
Traceback (most recent call last):
  File "C:\Users\flyin\PycharmProjects\skillFactory_D\venv\lib\site-packages\django\db\backends\utils.py", line 89, in _execute
    return self.cursor.execute(sql, params)
psycopg2.errors.UndefinedTable: ОШИБКА:  отношение "django_site" не существует
LINE 1: ..."django_site"."domain", "django_site"."name" FROM "django_si...
                                                             ^


The above exception was the direct cause of the following exception:

Traceback (most recent call last):
  File "C:\Users\flyin\PycharmProjects\skillFactory_D\venv\lib\site-packages\django\core\handlers\exception.py", line 55, in inner
    response = get_response(request)
  File "C:\Users\flyin\PycharmProjects\skillFactory_D\venv\lib\site-packages\django\utils\deprecation.py", line 136, in __call__
    response = self.process_response(request, response)
  File "C:\Users\flyin\PycharmProjects\skillFactory_D\venv\lib\site-packages\django\contrib\flatpages\middleware.py", line 12, in process_response
    return flatpage(request, request.path_info)
  File "C:\Users\flyin\PycharmProjects\skillFactory_D\venv\lib\site-packages\django\contrib\flatpages\views.py", line 35, in flatpage
    site_id = get_current_site(request).id
  File "C:\Users\flyin\PycharmProjects\skillFactory_D\venv\lib\site-packages\django\contrib\sites\shortcuts.py", line 16, in get_current_site
    return Site.objects.get_current(request)
  File "C:\Users\flyin\PycharmProjects\skillFactory_D\venv\lib\site-packages\django\contrib\sites\models.py", line 59, in get_current
    return self._get_site_by_id(site_id)
  File "C:\Users\flyin\PycharmProjects\skillFactory_D\venv\lib\site-packages\django\contrib\sites\models.py", line 30, in _get_site_by_id
    site = self.get(pk=site_id)
  File "C:\Users\flyin\PycharmProjects\skillFactory_D\venv\lib\site-packages\django\db\models\manager.py", line 87, in manager_method
    return getattr(self.get_queryset(), name)(*args, **kwargs)
  File "C:\Users\flyin\PycharmProjects\skillFactory_D\venv\lib\site-packages\django\db\models\query.py", line 633, in get
    num = len(clone)
  File "C:\Users\flyin\PycharmProjects\skillFactory_D\venv\lib\site-packages\django\db\models\query.py", line 380, in __len__
    self._fetch_all()
  File "C:\Users\flyin\PycharmProjects\skillFactory_D\venv\lib\site-packages\django\db\models\query.py", line 1881, in _fetch_all
    self._result_cache = list(self._iterable_class(self))
  File "C:\Users\flyin\PycharmProjects\skillFactory_D\venv\lib\site-packages\django\db\models\query.py", line 91, in __iter__
    results = compiler.execute_sql(
  File "C:\Users\flyin\PycharmProjects\skillFactory_D\venv\lib\site-packages\django\db\models\sql\compiler.py", line 1562, in execute_sql
    cursor.execute(sql, params)
  File "C:\Users\flyin\PycharmProjects\skillFactory_D\venv\lib\site-packages\django\db\backends\utils.py", line 102, in execute
    return super().execute(sql, params)
  File "C:\Users\flyin\PycharmProjects\skillFactory_D\venv\lib\site-packages\django\db\backends\utils.py", line 67, in execute
    return self._execute_with_wrappers(
  File "C:\Users\flyin\PycharmProjects\skillFactory_D\venv\lib\site-packages\django\db\backends\utils.py", line 80, in _execute_with_wrappers
    return executor(sql, params, many, context)
  File "C:\Users\flyin\PycharmProjects\skillFactory_D\venv\lib\site-packages\django\db\backends\utils.py", line 89, in _execute
    return self.cursor.execute(sql, params)
  File "C:\Users\flyin\PycharmProjects\skillFactory_D\venv\lib\site-packages\django\db\utils.py", line 91, in __exit__
    raise dj_exc_value.with_traceback(traceback) from exc_value
  File "C:\Users\flyin\PycharmProjects\skillFactory_D\venv\lib\site-packages\django\db\backends\utils.py", line 89, in _execute
    return self.cursor.execute(sql, params)
django.db.utils.ProgrammingError: ОШИБКА:  отношение "django_site" не существует
LINE 1: ..."django_site"."domain", "django_site"."name" FROM "django_si...
                                                             ^

[2023-07-13 15:27:19,655] * [ERROR] "GET /news/css/styles.css HTTP/1.1" 500 149045 C:\Users\flyin\PycharmProjects\skillFactory_D\venv\lib\site-packages\django\core\servers\basehttp.py None
[2023-07-13 15:27:22,905] * [ERROR] Internal Server Error: /about/ C:\Users\flyin\PycharmProjects\skillFactory_D\venv\lib\site-packages\django\utils\log.py (<class 'django.db.utils.ProgrammingError'>, ProgrammingError('ОШИБКА:  отношение "django_site" не существует\nLINE 1: ..."django_site"."domain", "django_site"."name" FROM "django_si...\n                                                             ^\n'), <traceback object at 0x000001ED3DEFA780>)
Traceback (most recent call last):
  File "C:\Users\flyin\PycharmProjects\skillFactory_D\venv\lib\site-packages\django\db\backends\utils.py", line 89, in _execute
    return self.cursor.execute(sql, params)
psycopg2.errors.UndefinedTable: ОШИБКА:  отношение "django_site" не существует
LINE 1: ..."django_site"."domain", "django_site"."name" FROM "django_si...
                                                             ^


The above exception was the direct cause of the following exception:

Traceback (most recent call last):
  File "C:\Users\flyin\PycharmProjects\skillFactory_D\venv\lib\site-packages\django\core\handlers\exception.py", line 55, in inner
    response = get_response(request)
  File "C:\Users\flyin\PycharmProjects\skillFactory_D\venv\lib\site-packages\django\utils\deprecation.py", line 136, in __call__
    response = self.process_response(request, response)
  File "C:\Users\flyin\PycharmProjects\skillFactory_D\venv\lib\site-packages\django\contrib\flatpages\middleware.py", line 12, in process_response
    return flatpage(request, request.path_info)
  File "C:\Users\flyin\PycharmProjects\skillFactory_D\venv\lib\site-packages\django\contrib\flatpages\views.py", line 35, in flatpage
    site_id = get_current_site(request).id
  File "C:\Users\flyin\PycharmProjects\skillFactory_D\venv\lib\site-packages\django\contrib\sites\shortcuts.py", line 16, in get_current_site
    return Site.objects.get_current(request)
  File "C:\Users\flyin\PycharmProjects\skillFactory_D\venv\lib\site-packages\django\contrib\sites\models.py", line 59, in get_current
    return self._get_site_by_id(site_id)
  File "C:\Users\flyin\PycharmProjects\skillFactory_D\venv\lib\site-packages\django\contrib\sites\models.py", line 30, in _get_site_by_id
    site = self.get(pk=site_id)
  File "C:\Users\flyin\PycharmProjects\skillFactory_D\venv\lib\site-packages\django\db\models\manager.py", line 87, in manager_method
    return getattr(self.get_queryset(), name)(*args, **kwargs)
  File "C:\Users\flyin\PycharmProjects\skillFactory_D\venv\lib\site-packages\django\db\models\query.py", line 633, in get
    num = len(clone)
  File "C:\Users\flyin\PycharmProjects\skillFactory_D\venv\lib\site-packages\django\db\models\query.py", line 380, in __len__
    self._fetch_all()
  File "C:\Users\flyin\PycharmProjects\skillFactory_D\venv\lib\site-packages\django\db\models\query.py", line 1881, in _fetch_all
    self._result_cache = list(self._iterable_class(self))
  File "C:\Users\flyin\PycharmProjects\skillFactory_D\venv\lib\site-packages\django\db\models\query.py", line 91, in __iter__
    results = compiler.execute_sql(
  File "C:\Users\flyin\PycharmProjects\skillFactory_D\venv\lib\site-packages\django\db\models\sql\compiler.py", line 1562, in execute_sql
    cursor.execute(sql, params)
  File "C:\Users\flyin\PycharmProjects\skillFactory_D\venv\lib\site-packages\django\db\backends\utils.py", line 102, in execute
    return super().execute(sql, params)
  File "C:\Users\flyin\PycharmProjects\skillFactory_D\venv\lib\site-packages\django\db\backends\utils.py", line 67, in execute
    return self._execute_with_wrappers(
  File "C:\Users\flyin\PycharmProjects\skillFactory_D\venv\lib\site-packages\django\db\backends\utils.py", line 80, in _execute_with_wrappers
    return executor(sql, params, many, context)
  File "C:\Users\flyin\PycharmProjects\skillFactory_D\venv\lib\site-packages\django\db\backends\utils.py", line 89, in _execute
    return self.cursor.execute(sql, params)
  File "C:\Users\flyin\PycharmProjects\skillFactory_D\venv\lib\site-packages\django\db\utils.py", line 91, in __exit__
    raise dj_exc_value.with_traceback(traceback) from exc_value
  File "C:\Users\flyin\PycharmProjects\skillFactory_D\venv\lib\site-packages\django\db\backends\utils.py", line 89, in _execute
    return self.cursor.execute(sql, params)
django.db.utils.ProgrammingError: ОШИБКА:  отношение "django_site" не существует
LINE 1: ..."django_site"."domain", "django_site"."name" FROM "django_si...
                                                             ^

[2023-07-13 15:27:22,941] * [ERROR] "GET /about/ HTTP/1.1" 500 149245 C:\Users\flyin\PycharmProjects\skillFactory_D\venv\lib\site-packages\django\core\servers\basehttp.py None
[2023-07-13 15:27:26,388] * [ERROR] Internal Server Error: /news/css/styles.css C:\Users\flyin\PycharmProjects\skillFactory_D\venv\lib\site-packages\django\utils\log.py (<class 'django.db.utils.ProgrammingError'>, ProgrammingError('ОШИБКА:  отношение "django_site" не существует\nLINE 1: ..."django_site"."domain", "django_site"."name" FROM "django_si...\n                                                             ^\n'), <traceback object at 0x000001ED3DDE3500>)
Traceback (most recent call last):
  File "C:\Users\flyin\PycharmProjects\skillFactory_D\venv\lib\site-packages\django\db\backends\utils.py", line 89, in _execute
    return self.cursor.execute(sql, params)
psycopg2.errors.UndefinedTable: ОШИБКА:  отношение "django_site" не существует
LINE 1: ..."django_site"."domain", "django_site"."name" FROM "django_si...
                                                             ^


The above exception was the direct cause of the following exception:

Traceback (most recent call last):
  File "C:\Users\flyin\PycharmProjects\skillFactory_D\venv\lib\site-packages\django\core\handlers\exception.py", line 55, in inner
    response = get_response(request)
  File "C:\Users\flyin\PycharmProjects\skillFactory_D\venv\lib\site-packages\django\utils\deprecation.py", line 136, in __call__
    response = self.process_response(request, response)
  File "C:\Users\flyin\PycharmProjects\skillFactory_D\venv\lib\site-packages\django\contrib\flatpages\middleware.py", line 12, in process_response
    return flatpage(request, request.path_info)
  File "C:\Users\flyin\PycharmProjects\skillFactory_D\venv\lib\site-packages\django\contrib\flatpages\views.py", line 35, in flatpage
    site_id = get_current_site(request).id
  File "C:\Users\flyin\PycharmProjects\skillFactory_D\venv\lib\site-packages\django\contrib\sites\shortcuts.py", line 16, in get_current_site
    return Site.objects.get_current(request)
  File "C:\Users\flyin\PycharmProjects\skillFactory_D\venv\lib\site-packages\django\contrib\sites\models.py", line 59, in get_current
    return self._get_site_by_id(site_id)
  File "C:\Users\flyin\PycharmProjects\skillFactory_D\venv\lib\site-packages\django\contrib\sites\models.py", line 30, in _get_site_by_id
    site = self.get(pk=site_id)
  File "C:\Users\flyin\PycharmProjects\skillFactory_D\venv\lib\site-packages\django\db\models\manager.py", line 87, in manager_method
    return getattr(self.get_queryset(), name)(*args, **kwargs)
  File "C:\Users\flyin\PycharmProjects\skillFactory_D\venv\lib\site-packages\django\db\models\query.py", line 633, in get
    num = len(clone)
  File "C:\Users\flyin\PycharmProjects\skillFactory_D\venv\lib\site-packages\django\db\models\query.py", line 380, in __len__
    self._fetch_all()
  File "C:\Users\flyin\PycharmProjects\skillFactory_D\venv\lib\site-packages\django\db\models\query.py", line 1881, in _fetch_all
    self._result_cache = list(self._iterable_class(self))
  File "C:\Users\flyin\PycharmProjects\skillFactory_D\venv\lib\site-packages\django\db\models\query.py", line 91, in __iter__
    results = compiler.execute_sql(
  File "C:\Users\flyin\PycharmProjects\skillFactory_D\venv\lib\site-packages\django\db\models\sql\compiler.py", line 1562, in execute_sql
    cursor.execute(sql, params)
  File "C:\Users\flyin\PycharmProjects\skillFactory_D\venv\lib\site-packages\django\db\backends\utils.py", line 102, in execute
    return super().execute(sql, params)
  File "C:\Users\flyin\PycharmProjects\skillFactory_D\venv\lib\site-packages\django\db\backends\utils.py", line 67, in execute
    return self._execute_with_wrappers(
  File "C:\Users\flyin\PycharmProjects\skillFactory_D\venv\lib\site-packages\django\db\backends\utils.py", line 80, in _execute_with_wrappers
    return executor(sql, params, many, context)
  File "C:\Users\flyin\PycharmProjects\skillFactory_D\venv\lib\site-packages\django\db\backends\utils.py", line 89, in _execute
    return self.cursor.execute(sql, params)
  File "C:\Users\flyin\PycharmProjects\skillFactory_D\venv\lib\site-packages\django\db\utils.py", line 91, in __exit__
    raise dj_exc_value.with_traceback(traceback) from exc_value
  File "C:\Users\flyin\PycharmProjects\skillFactory_D\venv\lib\site-packages\django\db\backends\utils.py", line 89, in _execute
    return self.cursor.execute(sql, params)
django.db.utils.ProgrammingError: ОШИБКА:  отношение "django_site" не существует
LINE 1: ..."django_site"."domain", "django_site"."name" FROM "django_si...
                                                             ^

[2023-07-13 15:27:26,417] * [ERROR] "GET /news/css/styles.css HTTP/1.1" 500 149045 C:\Users\flyin\PycharmProjects\skillFactory_D\venv\lib\site-packages\django\core\servers\basehttp.py None
[2023-07-14 00:29:54,505] * [ERROR] "GET /static/https%3A/cdn.jsdelivr.net/npm/bootstrap%405.1.3/dist/js/bootstrap.bundle.min.js HTTP/1.1" 500 59 C:\Users\flyin\PycharmProjects\skillFactory_D\venv\lib\site-packages\django\core\servers\basehttp.py None
[2023-07-14 00:29:56,341] * [ERROR] Internal Server Error: /news/subscribed/css/styles.css C:\Users\flyin\PycharmProjects\skillFactory_D\venv\lib\site-packages\django\utils\log.py (<class 'django.db.utils.ProgrammingError'>, ProgrammingError('ОШИБКА:  отношение "django_site" не существует\nLINE 1: ..."django_site"."domain", "django_site"."name" FROM "django_si...\n                                                             ^\n'), <traceback object at 0x000001ED3DFFDB00>)
Traceback (most recent call last):
  File "C:\Users\flyin\PycharmProjects\skillFactory_D\venv\lib\site-packages\django\db\backends\utils.py", line 89, in _execute
    return self.cursor.execute(sql, params)
psycopg2.errors.UndefinedTable: ОШИБКА:  отношение "django_site" не существует
LINE 1: ..."django_site"."domain", "django_site"."name" FROM "django_si...
                                                             ^


The above exception was the direct cause of the following exception:

Traceback (most recent call last):
  File "C:\Users\flyin\PycharmProjects\skillFactory_D\venv\lib\site-packages\django\core\handlers\exception.py", line 55, in inner
    response = get_response(request)
  File "C:\Users\flyin\PycharmProjects\skillFactory_D\venv\lib\site-packages\django\utils\deprecation.py", line 136, in __call__
    response = self.process_response(request, response)
  File "C:\Users\flyin\PycharmProjects\skillFactory_D\venv\lib\site-packages\django\contrib\flatpages\middleware.py", line 12, in process_response
    return flatpage(request, request.path_info)
  File "C:\Users\flyin\PycharmProjects\skillFactory_D\venv\lib\site-packages\django\contrib\flatpages\views.py", line 35, in flatpage
    site_id = get_current_site(request).id
  File "C:\Users\flyin\PycharmProjects\skillFactory_D\venv\lib\site-packages\django\contrib\sites\shortcuts.py", line 16, in get_current_site
    return Site.objects.get_current(request)
  File "C:\Users\flyin\PycharmProjects\skillFactory_D\venv\lib\site-packages\django\contrib\sites\models.py", line 59, in get_current
    return self._get_site_by_id(site_id)
  File "C:\Users\flyin\PycharmProjects\skillFactory_D\venv\lib\site-packages\django\contrib\sites\models.py", line 30, in _get_site_by_id
    site = self.get(pk=site_id)
  File "C:\Users\flyin\PycharmProjects\skillFactory_D\venv\lib\site-packages\django\db\models\manager.py", line 87, in manager_method
    return getattr(self.get_queryset(), name)(*args, **kwargs)
  File "C:\Users\flyin\PycharmProjects\skillFactory_D\venv\lib\site-packages\django\db\models\query.py", line 633, in get
    num = len(clone)
  File "C:\Users\flyin\PycharmProjects\skillFactory_D\venv\lib\site-packages\django\db\models\query.py", line 380, in __len__
    self._fetch_all()
  File "C:\Users\flyin\PycharmProjects\skillFactory_D\venv\lib\site-packages\django\db\models\query.py", line 1881, in _fetch_all
    self._result_cache = list(self._iterable_class(self))
  File "C:\Users\flyin\PycharmProjects\skillFactory_D\venv\lib\site-packages\django\db\models\query.py", line 91, in __iter__
    results = compiler.execute_sql(
  File "C:\Users\flyin\PycharmProjects\skillFactory_D\venv\lib\site-packages\django\db\models\sql\compiler.py", line 1562, in execute_sql
    cursor.execute(sql, params)
  File "C:\Users\flyin\PycharmProjects\skillFactory_D\venv\lib\site-packages\django\db\backends\utils.py", line 102, in execute
    return super().execute(sql, params)
  File "C:\Users\flyin\PycharmProjects\skillFactory_D\venv\lib\site-packages\django\db\backends\utils.py", line 67, in execute
    return self._execute_with_wrappers(
  File "C:\Users\flyin\PycharmProjects\skillFactory_D\venv\lib\site-packages\django\db\backends\utils.py", line 80, in _execute_with_wrappers
    return executor(sql, params, many, context)
  File "C:\Users\flyin\PycharmProjects\skillFactory_D\venv\lib\site-packages\django\db\backends\utils.py", line 89, in _execute
    return self.cursor.execute(sql, params)
  File "C:\Users\flyin\PycharmProjects\skillFactory_D\venv\lib\site-packages\django\db\utils.py", line 91, in __exit__
    raise dj_exc_value.with_traceback(traceback) from exc_value
  File "C:\Users\flyin\PycharmProjects\skillFactory_D\venv\lib\site-packages\django\db\backends\utils.py", line 89, in _execute
    return self.cursor.execute(sql, params)
django.db.utils.ProgrammingError: ОШИБКА:  отношение "django_site" не существует
LINE 1: ..."django_site"."domain", "django_site"."name" FROM "django_si...
                                                             ^

[2023-07-14 00:29:56,371] * [ERROR] "GET /news/subscribed/css/styles.css HTTP/1.1" 500 149203 C:\Users\flyin\PycharmProjects\skillFactory_D\venv\lib\site-packages\django\core\servers\basehttp.py None
[2023-07-14 00:29:57,859] * [ERROR] Internal Server Error: /news/subscribed/css/styles.css C:\Users\flyin\PycharmProjects\skillFactory_D\venv\lib\site-packages\django\utils\log.py (<class 'django.db.utils.ProgrammingError'>, ProgrammingError('ОШИБКА:  отношение "django_site" не существует\nLINE 1: ..."django_site"."domain", "django_site"."name" FROM "django_si...\n                                                             ^\n'), <traceback object at 0x000001ED3E1813C0>)
Traceback (most recent call last):
  File "C:\Users\flyin\PycharmProjects\skillFactory_D\venv\lib\site-packages\django\db\backends\utils.py", line 89, in _execute
    return self.cursor.execute(sql, params)
psycopg2.errors.UndefinedTable: ОШИБКА:  отношение "django_site" не существует
LINE 1: ..."django_site"."domain", "django_site"."name" FROM "django_si...
                                                             ^


The above exception was the direct cause of the following exception:

Traceback (most recent call last):
  File "C:\Users\flyin\PycharmProjects\skillFactory_D\venv\lib\site-packages\django\core\handlers\exception.py", line 55, in inner
    response = get_response(request)
  File "C:\Users\flyin\PycharmProjects\skillFactory_D\venv\lib\site-packages\django\utils\deprecation.py", line 136, in __call__
    response = self.process_response(request, response)
  File "C:\Users\flyin\PycharmProjects\skillFactory_D\venv\lib\site-packages\django\contrib\flatpages\middleware.py", line 12, in process_response
    return flatpage(request, request.path_info)
  File "C:\Users\flyin\PycharmProjects\skillFactory_D\venv\lib\site-packages\django\contrib\flatpages\views.py", line 35, in flatpage
    site_id = get_current_site(request).id
  File "C:\Users\flyin\PycharmProjects\skillFactory_D\venv\lib\site-packages\django\contrib\sites\shortcuts.py", line 16, in get_current_site
    return Site.objects.get_current(request)
  File "C:\Users\flyin\PycharmProjects\skillFactory_D\venv\lib\site-packages\django\contrib\sites\models.py", line 59, in get_current
    return self._get_site_by_id(site_id)
  File "C:\Users\flyin\PycharmProjects\skillFactory_D\venv\lib\site-packages\django\contrib\sites\models.py", line 30, in _get_site_by_id
    site = self.get(pk=site_id)
  File "C:\Users\flyin\PycharmProjects\skillFactory_D\venv\lib\site-packages\django\db\models\manager.py", line 87, in manager_method
    return getattr(self.get_queryset(), name)(*args, **kwargs)
  File "C:\Users\flyin\PycharmProjects\skillFactory_D\venv\lib\site-packages\django\db\models\query.py", line 633, in get
    num = len(clone)
  File "C:\Users\flyin\PycharmProjects\skillFactory_D\venv\lib\site-packages\django\db\models\query.py", line 380, in __len__
    self._fetch_all()
  File "C:\Users\flyin\PycharmProjects\skillFactory_D\venv\lib\site-packages\django\db\models\query.py", line 1881, in _fetch_all
    self._result_cache = list(self._iterable_class(self))
  File "C:\Users\flyin\PycharmProjects\skillFactory_D\venv\lib\site-packages\django\db\models\query.py", line 91, in __iter__
    results = compiler.execute_sql(
  File "C:\Users\flyin\PycharmProjects\skillFactory_D\venv\lib\site-packages\django\db\models\sql\compiler.py", line 1562, in execute_sql
    cursor.execute(sql, params)
  File "C:\Users\flyin\PycharmProjects\skillFactory_D\venv\lib\site-packages\django\db\backends\utils.py", line 102, in execute
    return super().execute(sql, params)
  File "C:\Users\flyin\PycharmProjects\skillFactory_D\venv\lib\site-packages\django\db\backends\utils.py", line 67, in execute
    return self._execute_with_wrappers(
  File "C:\Users\flyin\PycharmProjects\skillFactory_D\venv\lib\site-packages\django\db\backends\utils.py", line 80, in _execute_with_wrappers
    return executor(sql, params, many, context)
  File "C:\Users\flyin\PycharmProjects\skillFactory_D\venv\lib\site-packages\django\db\backends\utils.py", line 89, in _execute
    return self.cursor.execute(sql, params)
  File "C:\Users\flyin\PycharmProjects\skillFactory_D\venv\lib\site-packages\django\db\utils.py", line 91, in __exit__
    raise dj_exc_value.with_traceback(traceback) from exc_value
  File "C:\Users\flyin\PycharmProjects\skillFactory_D\venv\lib\site-packages\django\db\backends\utils.py", line 89, in _execute
    return self.cursor.execute(sql, params)
django.db.utils.ProgrammingError: ОШИБКА:  отношение "django_site" не существует
LINE 1: ..."django_site"."domain", "django_site"."name" FROM "django_si...
                                                             ^

[2023-07-14 00:29:57,869] * [ERROR] "GET /news/subscribed/css/styles.css HTTP/1.1" 500 149203 C:\Users\flyin\PycharmProjects\skillFactory_D\venv\lib\site-packages\django\core\servers\basehttp.py None
[2023-07-14 00:30:04,925] * [ERROR] Internal Server Error: /favicon.ico C:\Users\flyin\PycharmProjects\skillFactory_D\venv\lib\site-packages\django\utils\log.py (<class 'django.db.utils.ProgrammingError'>, ProgrammingError('ОШИБКА:  отношение "django_site" не существует\nLINE 1: ..."django_site"."domain", "django_site"."name" FROM "django_si...\n                                                             ^\n'), <traceback object at 0x000001ED3DDD0540>)
Traceback (most recent call last):
  File "C:\Users\flyin\PycharmProjects\skillFactory_D\venv\lib\site-packages\django\db\backends\utils.py", line 89, in _execute
    return self.cursor.execute(sql, params)
psycopg2.errors.UndefinedTable: ОШИБКА:  отношение "django_site" не существует
LINE 1: ..."django_site"."domain", "django_site"."name" FROM "django_si...
                                                             ^


The above exception was the direct cause of the following exception:

Traceback (most recent call last):
  File "C:\Users\flyin\PycharmProjects\skillFactory_D\venv\lib\site-packages\django\core\handlers\exception.py", line 55, in inner
    response = get_response(request)
  File "C:\Users\flyin\PycharmProjects\skillFactory_D\venv\lib\site-packages\django\utils\deprecation.py", line 136, in __call__
    response = self.process_response(request, response)
  File "C:\Users\flyin\PycharmProjects\skillFactory_D\venv\lib\site-packages\django\contrib\flatpages\middleware.py", line 12, in process_response
    return flatpage(request, request.path_info)
  File "C:\Users\flyin\PycharmProjects\skillFactory_D\venv\lib\site-packages\django\contrib\flatpages\views.py", line 35, in flatpage
    site_id = get_current_site(request).id
  File "C:\Users\flyin\PycharmProjects\skillFactory_D\venv\lib\site-packages\django\contrib\sites\shortcuts.py", line 16, in get_current_site
    return Site.objects.get_current(request)
  File "C:\Users\flyin\PycharmProjects\skillFactory_D\venv\lib\site-packages\django\contrib\sites\models.py", line 59, in get_current
    return self._get_site_by_id(site_id)
  File "C:\Users\flyin\PycharmProjects\skillFactory_D\venv\lib\site-packages\django\contrib\sites\models.py", line 30, in _get_site_by_id
    site = self.get(pk=site_id)
  File "C:\Users\flyin\PycharmProjects\skillFactory_D\venv\lib\site-packages\django\db\models\manager.py", line 87, in manager_method
    return getattr(self.get_queryset(), name)(*args, **kwargs)
  File "C:\Users\flyin\PycharmProjects\skillFactory_D\venv\lib\site-packages\django\db\models\query.py", line 633, in get
    num = len(clone)
  File "C:\Users\flyin\PycharmProjects\skillFactory_D\venv\lib\site-packages\django\db\models\query.py", line 380, in __len__
    self._fetch_all()
  File "C:\Users\flyin\PycharmProjects\skillFactory_D\venv\lib\site-packages\django\db\models\query.py", line 1881, in _fetch_all
    self._result_cache = list(self._iterable_class(self))
  File "C:\Users\flyin\PycharmProjects\skillFactory_D\venv\lib\site-packages\django\db\models\query.py", line 91, in __iter__
    results = compiler.execute_sql(
  File "C:\Users\flyin\PycharmProjects\skillFactory_D\venv\lib\site-packages\django\db\models\sql\compiler.py", line 1562, in execute_sql
    cursor.execute(sql, params)
  File "C:\Users\flyin\PycharmProjects\skillFactory_D\venv\lib\site-packages\django\db\backends\utils.py", line 102, in execute
    return super().execute(sql, params)
  File "C:\Users\flyin\PycharmProjects\skillFactory_D\venv\lib\site-packages\django\db\backends\utils.py", line 67, in execute
    return self._execute_with_wrappers(
  File "C:\Users\flyin\PycharmProjects\skillFactory_D\venv\lib\site-packages\django\db\backends\utils.py", line 80, in _execute_with_wrappers
    return executor(sql, params, many, context)
  File "C:\Users\flyin\PycharmProjects\skillFactory_D\venv\lib\site-packages\django\db\backends\utils.py", line 89, in _execute
    return self.cursor.execute(sql, params)
  File "C:\Users\flyin\PycharmProjects\skillFactory_D\venv\lib\site-packages\django\db\utils.py", line 91, in __exit__
    raise dj_exc_value.with_traceback(traceback) from exc_value
  File "C:\Users\flyin\PycharmProjects\skillFactory_D\venv\lib\site-packages\django\db\backends\utils.py", line 89, in _execute
    return self.cursor.execute(sql, params)
django.db.utils.ProgrammingError: ОШИБКА:  отношение "django_site" не существует
LINE 1: ..."django_site"."domain", "django_site"."name" FROM "django_si...
                                                             ^

[2023-07-14 00:30:04,938] * [ERROR] "GET /favicon.ico HTTP/1.1" 500 148972 C:\Users\flyin\PycharmProjects\skillFactory_D\venv\lib\site-packages\django\core\servers\basehttp.py None
[2023-07-15 16:20:49,580] * [ERROR] Internal Server Error: /accounts/login/ C:\Users\flyin\PycharmProjects\skillFactory_D\venv\lib\site-packages\django\utils\log.py (<class 'django.db.utils.ProgrammingError'>, ProgrammingError('ОШИБКА:  отношение "django_site" не существует\nLINE 1: ..."django_site"."domain", "django_site"."name" FROM "django_si...\n                                                             ^\n'), <traceback object at 0x0000022D8FA80AC0>)
Traceback (most recent call last):
  File "C:\Users\flyin\PycharmProjects\skillFactory_D\venv\lib\site-packages\django\db\backends\utils.py", line 89, in _execute
    return self.cursor.execute(sql, params)
psycopg2.errors.UndefinedTable: ОШИБКА:  отношение "django_site" не существует
LINE 1: ..."django_site"."domain", "django_site"."name" FROM "django_si...
                                                             ^


The above exception was the direct cause of the following exception:

Traceback (most recent call last):
  File "C:\Users\flyin\PycharmProjects\skillFactory_D\venv\lib\site-packages\django\core\handlers\exception.py", line 55, in inner
    response = get_response(request)
  File "C:\Users\flyin\PycharmProjects\skillFactory_D\venv\lib\site-packages\django\core\handlers\base.py", line 197, in _get_response
    response = wrapped_callback(request, *callback_args, **callback_kwargs)
  File "C:\Users\flyin\PycharmProjects\skillFactory_D\venv\lib\site-packages\django\views\generic\base.py", line 104, in view
    return self.dispatch(request, *args, **kwargs)
  File "C:\Users\flyin\PycharmProjects\skillFactory_D\venv\lib\site-packages\django\utils\decorators.py", line 46, in _wrapper
    return bound_method(*args, **kwargs)
  File "C:\Users\flyin\PycharmProjects\skillFactory_D\venv\lib\site-packages\django\views\decorators\debug.py", line 92, in sensitive_post_parameters_wrapper
    return view(request, *args, **kwargs)
  File "C:\Users\flyin\PycharmProjects\skillFactory_D\venv\lib\site-packages\allauth\account\views.py", line 149, in dispatch
    return super(LoginView, self).dispatch(request, *args, **kwargs)
  File "C:\Users\flyin\PycharmProjects\skillFactory_D\venv\lib\site-packages\allauth\account\views.py", line 77, in dispatch
    response = super(RedirectAuthenticatedUserMixin, self).dispatch(
  File "C:\Users\flyin\PycharmProjects\skillFactory_D\venv\lib\site-packages\django\views\generic\base.py", line 143, in dispatch
    return handler(request, *args, **kwargs)
  File "C:\Users\flyin\PycharmProjects\skillFactory_D\venv\lib\site-packages\allauth\account\views.py", line 93, in get
    response = super(AjaxCapableProcessFormViewMixin, self).get(
  File "C:\Users\flyin\PycharmProjects\skillFactory_D\venv\lib\site-packages\django\views\generic\edit.py", line 144, in get
    return self.render_to_response(self.get_context_data())
  File "C:\Users\flyin\PycharmProjects\skillFactory_D\venv\lib\site-packages\allauth\account\views.py", line 180, in get_context_data
    site = get_current_site(self.request)
  File "C:\Users\flyin\PycharmProjects\skillFactory_D\venv\lib\site-packages\django\contrib\sites\shortcuts.py", line 16, in get_current_site
    return Site.objects.get_current(request)
  File "C:\Users\flyin\PycharmProjects\skillFactory_D\venv\lib\site-packages\django\contrib\sites\models.py", line 59, in get_current
    return self._get_site_by_id(site_id)
  File "C:\Users\flyin\PycharmProjects\skillFactory_D\venv\lib\site-packages\django\contrib\sites\models.py", line 30, in _get_site_by_id
    site = self.get(pk=site_id)
  File "C:\Users\flyin\PycharmProjects\skillFactory_D\venv\lib\site-packages\django\db\models\manager.py", line 87, in manager_method
    return getattr(self.get_queryset(), name)(*args, **kwargs)
  File "C:\Users\flyin\PycharmProjects\skillFactory_D\venv\lib\site-packages\django\db\models\query.py", line 633, in get
    num = len(clone)
  File "C:\Users\flyin\PycharmProjects\skillFactory_D\venv\lib\site-packages\django\db\models\query.py", line 380, in __len__
    self._fetch_all()
  File "C:\Users\flyin\PycharmProjects\skillFactory_D\venv\lib\site-packages\django\db\models\query.py", line 1881, in _fetch_all
    self._result_cache = list(self._iterable_class(self))
  File "C:\Users\flyin\PycharmProjects\skillFactory_D\venv\lib\site-packages\django\db\models\query.py", line 91, in __iter__
    results = compiler.execute_sql(
  File "C:\Users\flyin\PycharmProjects\skillFactory_D\venv\lib\site-packages\django\db\models\sql\compiler.py", line 1562, in execute_sql
    cursor.execute(sql, params)
  File "C:\Users\flyin\PycharmProjects\skillFactory_D\venv\lib\site-packages\django\db\backends\utils.py", line 102, in execute
    return super().execute(sql, params)
  File "C:\Users\flyin\PycharmProjects\skillFactory_D\venv\lib\site-packages\django\db\backends\utils.py", line 67, in execute
    return self._execute_with_wrappers(
  File "C:\Users\flyin\PycharmProjects\skillFactory_D\venv\lib\site-packages\django\db\backends\utils.py", line 80, in _execute_with_wrappers
    return executor(sql, params, many, context)
  File "C:\Users\flyin\PycharmProjects\skillFactory_D\venv\lib\site-packages\django\db\backends\utils.py", line 89, in _execute
    return self.cursor.execute(sql, params)
  File "C:\Users\flyin\PycharmProjects\skillFactory_D\venv\lib\site-packages\django\db\utils.py", line 91, in __exit__
    raise dj_exc_value.with_traceback(traceback) from exc_value
  File "C:\Users\flyin\PycharmProjects\skillFactory_D\venv\lib\site-packages\django\db\backends\utils.py", line 89, in _execute
    return self.cursor.execute(sql, params)
django.db.utils.ProgrammingError: ОШИБКА:  отношение "django_site" не существует
LINE 1: ..."django_site"."domain", "django_site"."name" FROM "django_si...
                                                             ^

[2023-07-15 16:20:49,828] * [ERROR] "GET /accounts/login/?next=/ HTTP/1.1" 500 183778 C:\Users\flyin\PycharmProjects\skillFactory_D\venv\lib\site-packages\django\core\servers\basehttp.py None
[2023-07-15 16:20:52,670] * [ERROR] Internal Server Error: /favicon.ico C:\Users\flyin\PycharmProjects\skillFactory_D\venv\lib\site-packages\django\utils\log.py (<class 'django.db.utils.ProgrammingError'>, ProgrammingError('ОШИБКА:  отношение "django_site" не существует\nLINE 1: ..."django_site"."domain", "django_site"."name" FROM "django_si...\n                                                             ^\n'), <traceback object at 0x0000022D8FB459C0>)
Traceback (most recent call last):
  File "C:\Users\flyin\PycharmProjects\skillFactory_D\venv\lib\site-packages\django\db\backends\utils.py", line 89, in _execute
    return self.cursor.execute(sql, params)
psycopg2.errors.UndefinedTable: ОШИБКА:  отношение "django_site" не существует
LINE 1: ..."django_site"."domain", "django_site"."name" FROM "django_si...
                                                             ^


The above exception was the direct cause of the following exception:

Traceback (most recent call last):
  File "C:\Users\flyin\PycharmProjects\skillFactory_D\venv\lib\site-packages\django\core\handlers\exception.py", line 55, in inner
    response = get_response(request)
  File "C:\Users\flyin\PycharmProjects\skillFactory_D\venv\lib\site-packages\django\utils\deprecation.py", line 136, in __call__
    response = self.process_response(request, response)
  File "C:\Users\flyin\PycharmProjects\skillFactory_D\venv\lib\site-packages\django\contrib\flatpages\middleware.py", line 12, in process_response
    return flatpage(request, request.path_info)
  File "C:\Users\flyin\PycharmProjects\skillFactory_D\venv\lib\site-packages\django\contrib\flatpages\views.py", line 35, in flatpage
    site_id = get_current_site(request).id
  File "C:\Users\flyin\PycharmProjects\skillFactory_D\venv\lib\site-packages\django\contrib\sites\shortcuts.py", line 16, in get_current_site
    return Site.objects.get_current(request)
  File "C:\Users\flyin\PycharmProjects\skillFactory_D\venv\lib\site-packages\django\contrib\sites\models.py", line 59, in get_current
    return self._get_site_by_id(site_id)
  File "C:\Users\flyin\PycharmProjects\skillFactory_D\venv\lib\site-packages\django\contrib\sites\models.py", line 30, in _get_site_by_id
    site = self.get(pk=site_id)
  File "C:\Users\flyin\PycharmProjects\skillFactory_D\venv\lib\site-packages\django\db\models\manager.py", line 87, in manager_method
    return getattr(self.get_queryset(), name)(*args, **kwargs)
  File "C:\Users\flyin\PycharmProjects\skillFactory_D\venv\lib\site-packages\django\db\models\query.py", line 633, in get
    num = len(clone)
  File "C:\Users\flyin\PycharmProjects\skillFactory_D\venv\lib\site-packages\django\db\models\query.py", line 380, in __len__
    self._fetch_all()
  File "C:\Users\flyin\PycharmProjects\skillFactory_D\venv\lib\site-packages\django\db\models\query.py", line 1881, in _fetch_all
    self._result_cache = list(self._iterable_class(self))
  File "C:\Users\flyin\PycharmProjects\skillFactory_D\venv\lib\site-packages\django\db\models\query.py", line 91, in __iter__
    results = compiler.execute_sql(
  File "C:\Users\flyin\PycharmProjects\skillFactory_D\venv\lib\site-packages\django\db\models\sql\compiler.py", line 1562, in execute_sql
    cursor.execute(sql, params)
  File "C:\Users\flyin\PycharmProjects\skillFactory_D\venv\lib\site-packages\django\db\backends\utils.py", line 102, in execute
    return super().execute(sql, params)
  File "C:\Users\flyin\PycharmProjects\skillFactory_D\venv\lib\site-packages\django\db\backends\utils.py", line 67, in execute
    return self._execute_with_wrappers(
  File "C:\Users\flyin\PycharmProjects\skillFactory_D\venv\lib\site-packages\django\db\backends\utils.py", line 80, in _execute_with_wrappers
    return executor(sql, params, many, context)
  File "C:\Users\flyin\PycharmProjects\skillFactory_D\venv\lib\site-packages\django\db\backends\utils.py", line 89, in _execute
    return self.cursor.execute(sql, params)
  File "C:\Users\flyin\PycharmProjects\skillFactory_D\venv\lib\site-packages\django\db\utils.py", line 91, in __exit__
    raise dj_exc_value.with_traceback(traceback) from exc_value
  File "C:\Users\flyin\PycharmProjects\skillFactory_D\venv\lib\site-packages\django\db\backends\utils.py", line 89, in _execute
    return self.cursor.execute(sql, params)
django.db.utils.ProgrammingError: ОШИБКА:  отношение "django_site" не существует
LINE 1: ..."django_site"."domain", "django_site"."name" FROM "django_si...
                                                             ^

[2023-07-15 16:20:52,683] * [ERROR] "GET /favicon.ico HTTP/1.1" 500 148978 C:\Users\flyin\PycharmProjects\skillFactory_D\venv\lib\site-packages\django\core\servers\basehttp.py None
[2023-07-15 16:21:13,069] * [ERROR] Internal Server Error: /news/ C:\Users\flyin\PycharmProjects\skillFactory_D\venv\lib\site-packages\django\utils\log.py (<class 'django.db.utils.ProgrammingError'>, ProgrammingError('ОШИБКА:  отношение "news_news" не существует\nLINE 1: SELECT COUNT(*) AS "__count" FROM "news_news"\n                                          ^\n'), <traceback object at 0x0000022D8FB45D80>)
Traceback (most recent call last):
  File "C:\Users\flyin\PycharmProjects\skillFactory_D\venv\lib\site-packages\django\db\backends\utils.py", line 89, in _execute
    return self.cursor.execute(sql, params)
psycopg2.errors.UndefinedTable: ОШИБКА:  отношение "news_news" не существует
LINE 1: SELECT COUNT(*) AS "__count" FROM "news_news"
                                          ^


The above exception was the direct cause of the following exception:

Traceback (most recent call last):
  File "C:\Users\flyin\PycharmProjects\skillFactory_D\venv\lib\site-packages\django\core\handlers\exception.py", line 55, in inner
    response = get_response(request)
  File "C:\Users\flyin\PycharmProjects\skillFactory_D\venv\lib\site-packages\django\core\handlers\base.py", line 197, in _get_response
    response = wrapped_callback(request, *callback_args, **callback_kwargs)
  File "C:\Users\flyin\PycharmProjects\skillFactory_D\venv\lib\site-packages\django\views\generic\base.py", line 104, in view
    return self.dispatch(request, *args, **kwargs)
  File "C:\Users\flyin\PycharmProjects\skillFactory_D\venv\lib\site-packages\django\views\generic\base.py", line 143, in dispatch
    return handler(request, *args, **kwargs)
  File "C:\Users\flyin\PycharmProjects\skillFactory_D\venv\lib\site-packages\django\views\generic\list.py", line 174, in get
    context = self.get_context_data()
  File "C:\Users\flyin\PycharmProjects\skillFactory_D\project\news\views.py", line 30, in get_context_data
    context = super().get_context_data(**kwargs)
  File "C:\Users\flyin\PycharmProjects\skillFactory_D\venv\lib\site-packages\django\views\generic\list.py", line 128, in get_context_data
    paginator, page, queryset, is_paginated = self.paginate_queryset(
  File "C:\Users\flyin\PycharmProjects\skillFactory_D\venv\lib\site-packages\django\views\generic\list.py", line 73, in paginate_queryset
    page = paginator.page(page_number)
  File "C:\Users\flyin\PycharmProjects\skillFactory_D\venv\lib\site-packages\django\core\paginator.py", line 72, in page
    number = self.validate_number(number)
  File "C:\Users\flyin\PycharmProjects\skillFactory_D\venv\lib\site-packages\django\core\paginator.py", line 53, in validate_number
    if number > self.num_pages:
  File "C:\Users\flyin\PycharmProjects\skillFactory_D\venv\lib\site-packages\django\utils\functional.py", line 57, in __get__
    res = instance.__dict__[self.name] = self.func(instance)
  File "C:\Users\flyin\PycharmProjects\skillFactory_D\venv\lib\site-packages\django\core\paginator.py", line 99, in num_pages
    if self.count == 0 and not self.allow_empty_first_page:
  File "C:\Users\flyin\PycharmProjects\skillFactory_D\venv\lib\site-packages\django\utils\functional.py", line 57, in __get__
    res = instance.__dict__[self.name] = self.func(instance)
  File "C:\Users\flyin\PycharmProjects\skillFactory_D\venv\lib\site-packages\django\core\paginator.py", line 93, in count
    return c()
  File "C:\Users\flyin\PycharmProjects\skillFactory_D\venv\lib\site-packages\django\db\models\query.py", line 608, in count
    return self.query.get_count(using=self.db)
  File "C:\Users\flyin\PycharmProjects\skillFactory_D\venv\lib\site-packages\django\db\models\sql\query.py", line 557, in get_count
    return obj.get_aggregation(using, {"__count": Count("*")})["__count"]
  File "C:\Users\flyin\PycharmProjects\skillFactory_D\venv\lib\site-packages\django\db\models\sql\query.py", line 543, in get_aggregation
    result = compiler.execute_sql(SINGLE)
  File "C:\Users\flyin\PycharmProjects\skillFactory_D\venv\lib\site-packages\django\db\models\sql\compiler.py", line 1562, in execute_sql
    cursor.execute(sql, params)
  File "C:\Users\flyin\PycharmProjects\skillFactory_D\venv\lib\site-packages\django\db\backends\utils.py", line 102, in execute
    return super().execute(sql, params)
  File "C:\Users\flyin\PycharmProjects\skillFactory_D\venv\lib\site-packages\django\db\backends\utils.py", line 67, in execute
    return self._execute_with_wrappers(
  File "C:\Users\flyin\PycharmProjects\skillFactory_D\venv\lib\site-packages\django\db\backends\utils.py", line 80, in _execute_with_wrappers
    return executor(sql, params, many, context)
  File "C:\Users\flyin\PycharmProjects\skillFactory_D\venv\lib\site-packages\django\db\backends\utils.py", line 89, in _execute
    return self.cursor.execute(sql, params)
  File "C:\Users\flyin\PycharmProjects\skillFactory_D\venv\lib\site-packages\django\db\utils.py", line 91, in __exit__
    raise dj_exc_value.with_traceback(traceback) from exc_value
  File "C:\Users\flyin\PycharmProjects\skillFactory_D\venv\lib\site-packages\django\db\backends\utils.py", line 89, in _execute
    return self.cursor.execute(sql, params)
django.db.utils.ProgrammingError: ОШИБКА:  отношение "news_news" не существует
LINE 1: SELECT COUNT(*) AS "__count" FROM "news_news"
                                          ^

[2023-07-15 16:21:13,116] * [ERROR] "GET /news/ HTTP/1.1" 500 175220 C:\Users\flyin\PycharmProjects\skillFactory_D\venv\lib\site-packages\django\core\servers\basehttp.py None
[2023-07-15 16:21:15,284] * [ERROR] Internal Server Error: /favicon.ico C:\Users\flyin\PycharmProjects\skillFactory_D\venv\lib\site-packages\django\utils\log.py (<class 'django.db.utils.ProgrammingError'>, ProgrammingError('ОШИБКА:  отношение "django_site" не существует\nLINE 1: ..."django_site"."domain", "django_site"."name" FROM "django_si...\n                                                             ^\n'), <traceback object at 0x0000022D8FC791C0>)
Traceback (most recent call last):
  File "C:\Users\flyin\PycharmProjects\skillFactory_D\venv\lib\site-packages\django\db\backends\utils.py", line 89, in _execute
    return self.cursor.execute(sql, params)
psycopg2.errors.UndefinedTable: ОШИБКА:  отношение "django_site" не существует
LINE 1: ..."django_site"."domain", "django_site"."name" FROM "django_si...
                                                             ^


The above exception was the direct cause of the following exception:

Traceback (most recent call last):
  File "C:\Users\flyin\PycharmProjects\skillFactory_D\venv\lib\site-packages\django\core\handlers\exception.py", line 55, in inner
    response = get_response(request)
  File "C:\Users\flyin\PycharmProjects\skillFactory_D\venv\lib\site-packages\django\utils\deprecation.py", line 136, in __call__
    response = self.process_response(request, response)
  File "C:\Users\flyin\PycharmProjects\skillFactory_D\venv\lib\site-packages\django\contrib\flatpages\middleware.py", line 12, in process_response
    return flatpage(request, request.path_info)
  File "C:\Users\flyin\PycharmProjects\skillFactory_D\venv\lib\site-packages\django\contrib\flatpages\views.py", line 35, in flatpage
    site_id = get_current_site(request).id
  File "C:\Users\flyin\PycharmProjects\skillFactory_D\venv\lib\site-packages\django\contrib\sites\shortcuts.py", line 16, in get_current_site
    return Site.objects.get_current(request)
  File "C:\Users\flyin\PycharmProjects\skillFactory_D\venv\lib\site-packages\django\contrib\sites\models.py", line 59, in get_current
    return self._get_site_by_id(site_id)
  File "C:\Users\flyin\PycharmProjects\skillFactory_D\venv\lib\site-packages\django\contrib\sites\models.py", line 30, in _get_site_by_id
    site = self.get(pk=site_id)
  File "C:\Users\flyin\PycharmProjects\skillFactory_D\venv\lib\site-packages\django\db\models\manager.py", line 87, in manager_method
    return getattr(self.get_queryset(), name)(*args, **kwargs)
  File "C:\Users\flyin\PycharmProjects\skillFactory_D\venv\lib\site-packages\django\db\models\query.py", line 633, in get
    num = len(clone)
  File "C:\Users\flyin\PycharmProjects\skillFactory_D\venv\lib\site-packages\django\db\models\query.py", line 380, in __len__
    self._fetch_all()
  File "C:\Users\flyin\PycharmProjects\skillFactory_D\venv\lib\site-packages\django\db\models\query.py", line 1881, in _fetch_all
    self._result_cache = list(self._iterable_class(self))
  File "C:\Users\flyin\PycharmProjects\skillFactory_D\venv\lib\site-packages\django\db\models\query.py", line 91, in __iter__
    results = compiler.execute_sql(
  File "C:\Users\flyin\PycharmProjects\skillFactory_D\venv\lib\site-packages\django\db\models\sql\compiler.py", line 1562, in execute_sql
    cursor.execute(sql, params)
  File "C:\Users\flyin\PycharmProjects\skillFactory_D\venv\lib\site-packages\django\db\backends\utils.py", line 102, in execute
    return super().execute(sql, params)
  File "C:\Users\flyin\PycharmProjects\skillFactory_D\venv\lib\site-packages\django\db\backends\utils.py", line 67, in execute
    return self._execute_with_wrappers(
  File "C:\Users\flyin\PycharmProjects\skillFactory_D\venv\lib\site-packages\django\db\backends\utils.py", line 80, in _execute_with_wrappers
    return executor(sql, params, many, context)
  File "C:\Users\flyin\PycharmProjects\skillFactory_D\venv\lib\site-packages\django\db\backends\utils.py", line 89, in _execute
    return self.cursor.execute(sql, params)
  File "C:\Users\flyin\PycharmProjects\skillFactory_D\venv\lib\site-packages\django\db\utils.py", line 91, in __exit__
    raise dj_exc_value.with_traceback(traceback) from exc_value
  File "C:\Users\flyin\PycharmProjects\skillFactory_D\venv\lib\site-packages\django\db\backends\utils.py", line 89, in _execute
    return self.cursor.execute(sql, params)
django.db.utils.ProgrammingError: ОШИБКА:  отношение "django_site" не существует
LINE 1: ..."django_site"."domain", "django_site"."name" FROM "django_si...
                                                             ^

[2023-07-15 16:21:15,376] * [ERROR] "GET /favicon.ico HTTP/1.1" 500 148961 C:\Users\flyin\PycharmProjects\skillFactory_D\venv\lib\site-packages\django\core\servers\basehttp.py None
[2023-07-15 16:27:11,372] * [ERROR] Internal Server Error: /news/ C:\Users\flyin\PycharmProjects\skillFactory_D\venv\lib\site-packages\django\utils\log.py (<class 'django.core.exceptions.ImproperlyConfigured'>, ImproperlyConfigured('settings.DATABASES is improperly configured. Please supply the ENGINE value. Check settings documentation for more details.'), <traceback object at 0x000002CDAB689B80>)
Traceback (most recent call last):
  File "C:\Users\flyin\PycharmProjects\skillFactory_D\venv\lib\site-packages\django\core\handlers\exception.py", line 55, in inner
    response = get_response(request)
  File "C:\Users\flyin\PycharmProjects\skillFactory_D\venv\lib\site-packages\django\core\handlers\base.py", line 197, in _get_response
    response = wrapped_callback(request, *callback_args, **callback_kwargs)
  File "C:\Users\flyin\PycharmProjects\skillFactory_D\venv\lib\site-packages\django\views\generic\base.py", line 104, in view
    return self.dispatch(request, *args, **kwargs)
  File "C:\Users\flyin\PycharmProjects\skillFactory_D\venv\lib\site-packages\django\views\generic\base.py", line 143, in dispatch
    return handler(request, *args, **kwargs)
  File "C:\Users\flyin\PycharmProjects\skillFactory_D\venv\lib\site-packages\django\views\generic\list.py", line 174, in get
    context = self.get_context_data()
  File "C:\Users\flyin\PycharmProjects\skillFactory_D\project\news\views.py", line 30, in get_context_data
    context = super().get_context_data(**kwargs)
  File "C:\Users\flyin\PycharmProjects\skillFactory_D\venv\lib\site-packages\django\views\generic\list.py", line 128, in get_context_data
    paginator, page, queryset, is_paginated = self.paginate_queryset(
  File "C:\Users\flyin\PycharmProjects\skillFactory_D\venv\lib\site-packages\django\views\generic\list.py", line 73, in paginate_queryset
    page = paginator.page(page_number)
  File "C:\Users\flyin\PycharmProjects\skillFactory_D\venv\lib\site-packages\django\core\paginator.py", line 72, in page
    number = self.validate_number(number)
  File "C:\Users\flyin\PycharmProjects\skillFactory_D\venv\lib\site-packages\django\core\paginator.py", line 53, in validate_number
    if number > self.num_pages:
  File "C:\Users\flyin\PycharmProjects\skillFactory_D\venv\lib\site-packages\django\utils\functional.py", line 57, in __get__
    res = instance.__dict__[self.name] = self.func(instance)
  File "C:\Users\flyin\PycharmProjects\skillFactory_D\venv\lib\site-packages\django\core\paginator.py", line 99, in num_pages
    if self.count == 0 and not self.allow_empty_first_page:
  File "C:\Users\flyin\PycharmProjects\skillFactory_D\venv\lib\site-packages\django\utils\functional.py", line 57, in __get__
    res = instance.__dict__[self.name] = self.func(instance)
  File "C:\Users\flyin\PycharmProjects\skillFactory_D\venv\lib\site-packages\django\core\paginator.py", line 93, in count
    return c()
  File "C:\Users\flyin\PycharmProjects\skillFactory_D\venv\lib\site-packages\django\db\models\query.py", line 608, in count
    return self.query.get_count(using=self.db)
  File "C:\Users\flyin\PycharmProjects\skillFactory_D\venv\lib\site-packages\django\db\models\sql\query.py", line 557, in get_count
    return obj.get_aggregation(using, {"__count": Count("*")})["__count"]
  File "C:\Users\flyin\PycharmProjects\skillFactory_D\venv\lib\site-packages\django\db\models\sql\query.py", line 543, in get_aggregation
    result = compiler.execute_sql(SINGLE)
  File "C:\Users\flyin\PycharmProjects\skillFactory_D\venv\lib\site-packages\django\db\models\sql\compiler.py", line 1549, in execute_sql
    sql, params = self.as_sql()
  File "C:\Users\flyin\PycharmProjects\skillFactory_D\venv\lib\site-packages\django\db\models\sql\compiler.py", line 761, in as_sql
    from_, f_params = self.get_from_clause()
  File "C:\Users\flyin\PycharmProjects\skillFactory_D\venv\lib\site-packages\django\db\models\sql\compiler.py", line 1128, in get_from_clause
    clause_sql, clause_params = self.compile(from_clause)
  File "C:\Users\flyin\PycharmProjects\skillFactory_D\venv\lib\site-packages\django\db\models\sql\compiler.py", line 546, in compile
    sql, params = node.as_sql(self, self.connection)
  File "C:\Users\flyin\PycharmProjects\skillFactory_D\venv\lib\site-packages\django\db\models\sql\datastructures.py", line 203, in as_sql
    base_sql = compiler.quote_name_unless_alias(self.table_name)
  File "C:\Users\flyin\PycharmProjects\skillFactory_D\venv\lib\site-packages\django\db\models\sql\compiler.py", line 537, in quote_name_unless_alias
    r = self.connection.ops.quote_name(name)
  File "C:\Users\flyin\PycharmProjects\skillFactory_D\venv\lib\site-packages\django\db\backends\dummy\base.py", line 20, in complain
    raise ImproperlyConfigured(
django.core.exceptions.ImproperlyConfigured: settings.DATABASES is improperly configured. Please supply the ENGINE value. Check settings documentation for more details.
[2023-07-15 16:27:11,398] * [ERROR] "GET /news/ HTTP/1.1" 500 168062 C:\Users\flyin\PycharmProjects\skillFactory_D\venv\lib\site-packages\django\core\servers\basehttp.py None
[2023-07-15 16:27:12,990] * [ERROR] Internal Server Error: /favicon.ico C:\Users\flyin\PycharmProjects\skillFactory_D\venv\lib\site-packages\django\utils\log.py (<class 'django.core.exceptions.ImproperlyConfigured'>, ImproperlyConfigured('settings.DATABASES is improperly configured. Please supply the ENGINE value. Check settings documentation for more details.'), <traceback object at 0x000002CDAB91D280>)
Traceback (most recent call last):
  File "C:\Users\flyin\PycharmProjects\skillFactory_D\venv\lib\site-packages\django\core\handlers\exception.py", line 55, in inner
    response = get_response(request)
  File "C:\Users\flyin\PycharmProjects\skillFactory_D\venv\lib\site-packages\django\utils\deprecation.py", line 136, in __call__
    response = self.process_response(request, response)
  File "C:\Users\flyin\PycharmProjects\skillFactory_D\venv\lib\site-packages\django\contrib\flatpages\middleware.py", line 12, in process_response
    return flatpage(request, request.path_info)
  File "C:\Users\flyin\PycharmProjects\skillFactory_D\venv\lib\site-packages\django\contrib\flatpages\views.py", line 35, in flatpage
    site_id = get_current_site(request).id
  File "C:\Users\flyin\PycharmProjects\skillFactory_D\venv\lib\site-packages\django\contrib\sites\shortcuts.py", line 16, in get_current_site
    return Site.objects.get_current(request)
  File "C:\Users\flyin\PycharmProjects\skillFactory_D\venv\lib\site-packages\django\contrib\sites\models.py", line 59, in get_current
    return self._get_site_by_id(site_id)
  File "C:\Users\flyin\PycharmProjects\skillFactory_D\venv\lib\site-packages\django\contrib\sites\models.py", line 30, in _get_site_by_id
    site = self.get(pk=site_id)
  File "C:\Users\flyin\PycharmProjects\skillFactory_D\venv\lib\site-packages\django\db\models\manager.py", line 87, in manager_method
    return getattr(self.get_queryset(), name)(*args, **kwargs)
  File "C:\Users\flyin\PycharmProjects\skillFactory_D\venv\lib\site-packages\django\db\models\query.py", line 633, in get
    num = len(clone)
  File "C:\Users\flyin\PycharmProjects\skillFactory_D\venv\lib\site-packages\django\db\models\query.py", line 380, in __len__
    self._fetch_all()
  File "C:\Users\flyin\PycharmProjects\skillFactory_D\venv\lib\site-packages\django\db\models\query.py", line 1881, in _fetch_all
    self._result_cache = list(self._iterable_class(self))
  File "C:\Users\flyin\PycharmProjects\skillFactory_D\venv\lib\site-packages\django\db\models\query.py", line 91, in __iter__
    results = compiler.execute_sql(
  File "C:\Users\flyin\PycharmProjects\skillFactory_D\venv\lib\site-packages\django\db\models\sql\compiler.py", line 1549, in execute_sql
    sql, params = self.as_sql()
  File "C:\Users\flyin\PycharmProjects\skillFactory_D\venv\lib\site-packages\django\db\models\sql\compiler.py", line 736, in as_sql
    extra_select, order_by, group_by = self.pre_sql_setup(
  File "C:\Users\flyin\PycharmProjects\skillFactory_D\venv\lib\site-packages\django\db\models\sql\compiler.py", line 84, in pre_sql_setup
    self.setup_query(with_col_aliases=with_col_aliases)
  File "C:\Users\flyin\PycharmProjects\skillFactory_D\venv\lib\site-packages\django\db\models\sql\compiler.py", line 73, in setup_query
    self.select, self.klass_info, self.annotation_col_map = self.get_select(
  File "C:\Users\flyin\PycharmProjects\skillFactory_D\venv\lib\site-packages\django\db\models\sql\compiler.py", line 296, in get_select
    sql, params = self.compile(col)
  File "C:\Users\flyin\PycharmProjects\skillFactory_D\venv\lib\site-packages\django\db\models\sql\compiler.py", line 546, in compile
    sql, params = node.as_sql(self, self.connection)
  File "C:\Users\flyin\PycharmProjects\skillFactory_D\venv\lib\site-packages\django\db\models\expressions.py", line 1133, in as_sql
    sql = ".".join(map(compiler.quote_name_unless_alias, identifiers))
  File "C:\Users\flyin\PycharmProjects\skillFactory_D\venv\lib\site-packages\django\db\models\sql\compiler.py", line 537, in quote_name_unless_alias
    r = self.connection.ops.quote_name(name)
  File "C:\Users\flyin\PycharmProjects\skillFactory_D\venv\lib\site-packages\django\db\backends\dummy\base.py", line 20, in complain
    raise ImproperlyConfigured(
django.core.exceptions.ImproperlyConfigured: settings.DATABASES is improperly configured. Please supply the ENGINE value. Check settings documentation for more details.
[2023-07-15 16:27:13,208] * [ERROR] "GET /favicon.ico HTTP/1.1" 500 148122 C:\Users\flyin\PycharmProjects\skillFactory_D\venv\lib\site-packages\django\core\servers\basehttp.py None
[2023-07-15 16:28:02,575] * [ERROR] "GET /static/https%3A/cdn.jsdelivr.net/npm/bootstrap%405.1.3/dist/js/bootstrap.bundle.min.js HTTP/1.1" 500 59 C:\Users\flyin\PycharmProjects\skillFactory_D\venv\lib\site-packages\django\core\servers\basehttp.py None
